Workbook
Name Slicer_Employee_Name: #N/A
Name Slicer_Month: #N/A

Sheet Pivot Tables from Structured Da
J1: Month | K1: (All)
J2: Department | K2: (All)
A3: Total Revenue | B3: Product | P3: Employee | Q3: Sum of Units Sold | U3: Employee | V3: Count of Units Sold
A4: Region | B4: Central | C4: East | D4: North | E4: South | F4: West | G4: Grand Total | J4: Employee | K4: Average of Units Sold | P4: Christi Davis | Q4: 516 | U4: Electronics | V4: 41
A5: Electronics | B5: 566781 | C5: 320173 | D5: 418352 | E5: 576603 | F5: 355817 | G5: 2237726 | J5: Christi Davis | K5: 34.4 | P5: Fatima Zhang | Q5: 517 | U5: Furniture | V5: 24
A6: Furniture | B6: 218758 | C6: 461903 | D6: 129402 | E6: 467469 | F6: 141979 | G6: 1419511 | J6: Fatima Zhang | K6: 36.928571 | P6: Joe Lyn | Q6: 694 | U6: Stationery | V6: 35
A7: Stationery | B7: 300813 | C7: 563084 | D7: 602055 | E7: 525464 | F7: 212628 | G7: 2204044 | J7: Joe Lyn | K7: 46.266667 | P7: John Taylor | Q7: 464 | U7: Grand Total | V7: 100
A8: Grand Total | B8: 1086352 | C8: 1345160 | D8: 1149809 | E8: 1569536 | F8: 710424 | G8: 5861281 | J8: John Taylor | K8: 46.4 | P8: Lynda Smith | Q8: 366
J9: Lynda Smith | K9: 36.6 | P9: Martina Brands | Q9: 486
J10: Martina Brands | K10: 40.5 | P10: Raj Mehta | Q10: 548
J11: Raj Mehta | K11: 42.153846 | P11: Ronn Robinson | Q11: 473
E12: =GETPIVOTDATA("Revenue",$A$3) -> 5861281 | J12: Ronn Robinson | K12: 43 | P12: Grand Total | Q12: 4064
J13: Grand Total | K13: 40.64
K14: =GETPIVOTDATA("Units Sold",$J$4) -> 40.64 | Q14: =GETPIVOTDATA("Units Sold",$P$3) -> 4064

Sheet Dashbaord

Sheet XLOOKUP for Dynamic Cross-Sheet
A1: Employee Name | B1: Designation | C1: Region | D1: Revenue | E1: Target | F1: Sales Target Achievement %
A2: =IFERROR(_xlfn.XLOOKUP(MonthlySalesData!D2,EmployeeMaster!A:A,EmployeeMaster!B:B,0),0) -> Raj Mehta | B2: =IFERROR(_xlfn.XLOOKUP(MonthlySalesData!D2,EmployeeMaster!A:A,EmployeeMaster!D:D,0),0) -> Marketing Lead | C2: =IFERROR(_xlfn.XLOOKUP(MonthlySalesData!D2,EmployeeMaster!A:A,EmployeeMaster!E:E,0),0) -> South | D2: 36939 | E2: 37433 | F2: =IFERROR(D2/E2,0) -> 0.98680309
A3: =IFERROR(_xlfn.XLOOKUP(MonthlySalesData!D3,EmployeeMaster!A:A,EmployeeMaster!B:B,0),0) -> Ronn Robinson | B3: =IFERROR(_xlfn.XLOOKUP(MonthlySalesData!D3,EmployeeMaster!A:A,EmployeeMaster!D:D,0),0) -> Sr. Sales Exec. | C3: =IFERROR(_xlfn.XLOOKUP(MonthlySalesData!D3,EmployeeMaster!A:A,EmployeeMaster!E:E,0),0) -> East | D3: 43992 | E3: 36857 | F3: =IFERROR(D3/E3,0) -> 1.193586
A4: =IFERROR(_xlfn.XLOOKUP(MonthlySalesData!D4,EmployeeMaster!A:A,EmployeeMaster!B:B,0),0) -> Martina Brands | B4: =IFERROR(_xlfn.XLOOKUP(MonthlySalesData!D4,EmployeeMaster!A:A,EmployeeMaster!D:D,0),0) -> Brand Manager | C4: =IFERROR(_xlfn.XLOOKUP(MonthlySalesData!D4,EmployeeMaster!A:A,EmployeeMaster!E:E,0),0) -> North | D4: 22660 | E4: 26125 | F4: =IFERROR(D4/E4,0) -> 0.86736842
A5: =IFERROR(_xlfn.XLOOKUP(MonthlySalesData!D5,EmployeeMaster!A:A,EmployeeMaster!B:B,0),0) -> Lynda Smith | B5: =IFERROR(_xlfn.XLOOKUP(MonthlySalesData!D5,EmployeeMaster!A:A,EmployeeMaster!D:D,0),0) -> Sales Executive | C5: =IFERROR(_xlfn.XLOOKUP(MonthlySalesData!D5,EmployeeMaster!A:A,EmployeeMaster!E:E,0),0) -> North | D5: 66165 | E5: 59434 | F5: =IFERROR(D5/E5,0) -> 1.1132517
A6: =IFERROR(_xlfn.XLOOKUP(MonthlySalesData!D6,EmployeeMaster!A:A,EmployeeMaster!B:B,0),0) -> Martina Brands | B6: =IFERROR(_xlfn.XLOOKUP(MonthlySalesData!D6,EmployeeMaster!A:A,EmployeeMaster!D:D,0),0) -> Brand Manager | C6: =IFERROR(_xlfn.XLOOKUP(MonthlySalesData!D6,EmployeeMaster!A:A,EmployeeMaster!E:E,0),0) -> North | D6: 49606 | E6: 44952 | F6: =IFERROR(D6/E6,0) -> 1.1035327
A7: =IFERROR(_xlfn.XLOOKUP(MonthlySalesData!D7,EmployeeMaster!A:A,EmployeeMaster!B:B,0),0) -> Ronn Robinson | B7: =IFERROR(_xlfn.XLOOKUP(MonthlySalesData!D7,EmployeeMaster!A:A,EmployeeMaster!D:D,0),0) -> Sr. Sales Exec. | C7: =IFERROR(_xlfn.XLOOKUP(MonthlySalesData!D7,EmployeeMaster!A:A,EmployeeMaster!E:E,0),0) -> East | D7: 63356 | E7: 63804 | F7: =IFERROR(D7/E7,0) -> 0.9929785
A8: =IFERROR(_xlfn.XLOOKUP(MonthlySalesData!D8,EmployeeMaster!A:A,EmployeeMaster!B:B,0),0) -> Fatima Zhang | B8: =IFERROR(_xlfn.XLOOKUP(MonthlySalesData!D8,EmployeeMaster!A:A,EmployeeMaster!D:D,0),0) -> Sales Executive | C8: =IFERROR(_xlfn.XLOOKUP(MonthlySalesData!D8,EmployeeMaster!A:A,EmployeeMaster!E:E,0),0) -> South | D8: 28444 | E8: 27220 | F8: =IFERROR(D8/E8,0) -> 1.0449669
A9: =IFERROR(_xlfn.XLOOKUP(MonthlySalesData!D9,EmployeeMaster!A:A,EmployeeMaster!B:B,0),0) -> Fatima Zhang | B9: =IFERROR(_xlfn.XLOOKUP(MonthlySalesData!D9,EmployeeMaster!A:A,EmployeeMaster!D:D,0),0) -> Sales Executive | C9: =IFERROR(_xlfn.XLOOKUP(MonthlySalesData!D9,EmployeeMaster!A:A,EmployeeMaster!E:E,0),0) -> South | D9: 73660 | E9: 65437 | F9: =IFERROR(D9/E9,0) -> 1.1256629
A10: =IFERROR(_xlfn.XLOOKUP(MonthlySalesData!D10,EmployeeMaster!A:A,EmployeeMaster!B:B,0),0) -> John Taylor | B10: =IFERROR(_xlfn.XLOOKUP(MonthlySalesData!D10,EmployeeMaster!A:A,EmployeeMaster!D:D,0),0) -> Sales Manager | C10: =IFERROR(_xlfn.XLOOKUP(MonthlySalesData!D10,EmployeeMaster!A:A,EmployeeMaster!E:E,0),0) -> East | D10: 60858 | E10: 59657 | F10: =IFERROR(D10/E10,0) -> 1.0201318
A11: =IFERROR(_xlfn.XLOOKUP(MonthlySalesData!D11,EmployeeMaster!A:A,EmployeeMaster!B:B,0),0) -> Joe Lyn | B11: =IFERROR(_xlfn.XLOOKUP(MonthlySalesData!D11,EmployeeMaster!A:A,EmployeeMaster!D:D,0),0) -> Sales Associate | C11: =IFERROR(_xlfn.XLOOKUP(MonthlySalesData!D11,EmployeeMaster!A:A,EmployeeMaster!E:E,0),0) -> Central | D11: 97980 | E11: 88473 | F11: =IFERROR(D11/E11,0) -> 1.1074565
A12: =IFERROR(_xlfn.XLOOKUP(MonthlySalesData!D12,EmployeeMaster!A:A,EmployeeMaster!B:B,0),0) -> Christi Davis | B12: =IFERROR(_xlfn.XLOOKUP(MonthlySalesData!D12,EmployeeMaster!A:A,EmployeeMaster!D:D,0),0) -> Ops Manager | C12: =IFERROR(_xlfn.XLOOKUP(MonthlySalesData!D12,EmployeeMaster!A:A,EmployeeMaster!E:E,0),0) -> West | D12: 25104 | E12: 19270 | F12: =IFERROR(D12/E12,0) -> 1.3027504
A13: =IFERROR(_xlfn.XLOOKUP(MonthlySalesData!D13,EmployeeMaster!A:A,EmployeeMaster!B:B,0),0) -> Raj Mehta | B13: =IFERROR(_xlfn.XLOOKUP(MonthlySalesData!D13,EmployeeMaster!A:A,EmployeeMaster!D:D,0),0) -> Marketing Lead | C13: =IFERROR(_xlfn.XLOOKUP(MonthlySalesData!D13,EmployeeMaster!A:A,EmployeeMaster!E:E,0),0) -> South | D13: 64158 | E13: 67504 | F13: =IFERROR(D13/E13,0) -> 0.95043257
... A101: =IFERROR(_xlfn.XLOOKUP(MonthlySalesData!D101,EmployeeMaster!A:A,EmployeeMaster!B:B,0),0) -> Martina Brands | B101: =IFERROR(_xlfn.XLOOKUP(MonthlySalesData!D101,EmployeeMaster!A:A,EmployeeMaster!D:D,0),0) -> Brand Manager | C101: =IFERROR(_xlfn.XLOOKUP(MonthlySalesData!D101,EmployeeMaster!A:A,EmployeeMaster!E:E,0),0) -> North | D101: 71859 | E101: 72862 | F101: =IFERROR(D101/E101,0) -> 0.98623425

Sheet EmployeeMaster
A1: Employee ID | B1: Employee | C1: Department | D1: Designation | E1: Region | F1: Date of Joining | G1: Status
A2: EMP001 | B2: Lynda Smith | C2: Sales | D2: Sales Executive | E2: North | F2: 03/01/2019 | G2: Active
A3: EMP002 | B3: Raj Mehta | C3: Marketing | D3: Marketing Lead | E3: South | F3: 07/15/2020 | G3: Active
A4: EMP003 | B4: Ronn Robinson | C4: Sales | D4: Sr. Sales Exec. | E4: East | F4: 11/20/2018 | G4: Inactive
A5: EMP004 | B5: Christi Davis | C5: Operations | D5: Ops Manager | E5: West | F5: 01/10/2021 | G5: Active
A6: EMP005 | B6: Joe Lyn | C6: Sales | D6: Sales Associate | E6: Central | F6: 05/05/2020 | G6: Active
A7: EMP006 | B7: Fatima Zhang | C7: Sales | D7: Sales Executive | E7: South | F7: 08/30/2019 | G7: Active
A8: EMP007 | B8: Martina Brands | C8: Marketing | D8: Brand Manager | E8: North | F8: 02/17/2021 | G8: Active
A9: EMP008 | B9: John Taylor | C9: Sales | D9: Sales Manager | E9: East | F9: 06/23/2017 | G9: Inactive

Sheet Advanced Reporting  Calculated 
A3: Row Labels | B3: Sum of Bonus
A4: EMP001 | B4: 17427.35
A5: EMP002 | B5: 20234.25
A6: EMP003 | B6: 21144.15
A7: EMP004 | B7: 21501.4
A8: EMP005 | B8: 42687.1
A9: EMP006 | B9: 30824
A10: EMP007 | B10: 12846.6
A11: EMP008 | B11: 14691.15
A12: Grand Total | B12: 181356

Sheet Quarter unit sold
A3: Row Labels | B3: Sum of Units Sold
A4: Qtr1 | B4: 976
A5: Qtr2 | B5: 876
A6: Qtr3 | B6: 705
A7: Qtr4 | B7: 1507
A8: Grand Total | B8: 4064

Sheet Brainstorming Reflection
Q1: 3. West region showed declining performance after grouping by month
I2: 2 | J2: No employees who met their targets across all months..
A3: Sum of Revenue | B3: Column Labels | Q3: Count of Region2 | R3: Column Labels
A4: Row Labels | B4: Marketing | C4: Operations | D4: Sales | E4: Grand Total | J4: Row Labels | K4: Count of Quarters (Sale Date) | Q4: Row Labels | R4: January | S4: February | T4: March | U4: April | V4: May | W4: June | X4: July | Y4: August | Z4: September | AA4: October | AB4: November | AC4: December | AD4: Grand Total
A5: Qtr1 | B5: 449611 | D5: 982872 | E5: 1432483 | J5: Christi Davis | K5: 15 | Q5: Central | S5: 1 | T5: 1 | V5: 2 | W5: 1 | X5: 2 | Z5: 1 | AA5: 2 | AB5: 3 | AC5: 2 | AD5: 15
A6: Qtr2 | B6: 231500 | C6: 110468 | D6: 856594 | E6: 1198562 | J6: No | K6: 5 | Q6: East | R6: 2 | S6: 4 | T6: 1 | V6: 3 | W6: 1 | X6: 1 | Y6: 2 | AA6: 4 | AC6: 3 | AD6: 21
A7: Qtr3 | B7: 119878 | C7: 284448 | D7: 611296 | E7: 1015622 | J7: 45120 | K7: 1 | Q7: North | R7: 1 | S7: 3 | T7: 1 | U7: 1 | V7: 2 | X7: 2 | Y7: 1 | Z7: 1 | AA7: 3 | AB7: 3 | AC7: 4 | AD7: 22
A8: Qtr4 | B8: 696575 | C8: 315508 | D8: 1202531 | E8: 2214614 | J8: 45179 | K8: 1 | Q8: South | R8: 3 | S8: 4 | T8: 2 | U8: 3 | V8: 1 | W8: 3 | X8: 1 | Y8: 1 | AA8: 2 | AB8: 3 | AC8: 4 | AD8: 27
A9: Grand Total | B9: 1497564 | C9: 710424 | D9: 3653293 | E9: 5861281 | J9: 45192 | K9: 1 | Q9: West | V9: 2 | W9: 1 | X9: 4 | Z9: 2 | AA9: 3 | AB9: 1 | AC9: 2 | AD9: 15
J10: 45217 | K10: 1 | Q10: Grand Total | R10: 6 | S10: 12 | T10: 5 | U10: 4 | V10: 10 | W10: 6 | X10: 10 | Y10: 4 | Z10: 4 | AA10: 14 | AB10: 10 | AC10: 15 | AD10: 100
B11: highest total revenue in quarter | J11: 45285 | K11: 1
B12: Quarter 1 | C12: Marketing | J12: Ture | K12: 10
B13: Quarter 2 | C13: Sales | J13: 45054 | K13: 1
B14: Quarter 3 | C14: Sales | J14: 45068 | K14: 1
B15: Quarter 4 | C15: Sales | J15: 45105 | K15: 1
J16: 45123 | K16: 1
J17: 45124 | K17: 1
J18: 45132 | K18: 1
J19: 45215 | K19: 1
J20: 45216 | K20: 1
J21: 45258 | K21: 1
J22: 45285 | K22: 1
J23: Fatima Zhang | K23: 14
J24: No | K24: 2
J25: 45092 | K25: 1
J26: 45164 | K26: 1
J27: Ture | K27: 12
J28: 44944 | K28: 1
J29: 44970 | K29: 1
J30: 44992 | K30: 1
J31: 45011 | K31: 1
J32: 45017 | K32: 1
J33: 45028 | K33: 1
J34: 45084 | K34: 1
J35: 45088 | K35: 1
J36: 45128 | K36: 1
J37: 45210 | K37: 1
J38: 45252 | K38: 1
J39: 45283 | K39: 1
J40: Joe Lyn | K40: 15
...

Sheet MonthlySalesData
A1: Transaction ID | B1: Sale Date | C1: Employee Name | D1: Employee ID | E1: Month | F1: Department | G1: Product Category | H1: Units Sold | I1: Revenue | J1: Target | K1: Region | L1: Bench Marks | M1: Bonus | N1: Target achieved | O1: Month 2
A2: 770265 | B2: 44979 | C2: =_xlfn.XLOOKUP(D2,EmployeeMaster!A:A,EmployeeMaster!B:B,0) -> Raj Mehta | D2: EMP002 | E2: JAN | F2: =_xlfn.XLOOKUP(D2,EmployeeMaster!A:A,EmployeeMaster!C:C,0) -> Marketing | G2: Electronics | H2: 21 | I2: 36939 | J2: 37433 | K2: South | L2: =_xlfn.XLOOKUP(K2,RegionBenchmarks!A:A,RegionBenchmarks!B:B,"Not Found") -> 60000 | M2: =IF(I2>=J2,I2*5%,0) -> 0 | N2: =IF(I2>=J2,"Ture","No") -> No | O2: =TEXT(B2,"mmmm") -> February
A3: 562322 | B3: 45210 | C3: =_xlfn.XLOOKUP(D3,EmployeeMaster!A:A,EmployeeMaster!B:B,0) -> Ronn Robinson | D3: EMP003 | E3: JAN | F3: =_xlfn.XLOOKUP(D3,EmployeeMaster!A:A,EmployeeMaster!C:C,0) -> Sales | G3: Electronics | H3: 26 | I3: 43992 | J3: 36857 | K3: East | L3: =_xlfn.XLOOKUP(K3,RegionBenchmarks!A:A,RegionBenchmarks!B:B,"Not Found") -> 50000 | M3: =IF(I3>=J3,I3*5%,0) -> 2199.6 | N3: =IF(I3>=J3,"Ture","No") -> Ture | O3: =TEXT(B3,"mmmm") -> October
A4: 897935 | B4: 45051 | C4: =_xlfn.XLOOKUP(D4,EmployeeMaster!A:A,EmployeeMaster!B:B,0) -> Martina Brands | D4: EMP007 | E4: JAN | F4: =_xlfn.XLOOKUP(D4,EmployeeMaster!A:A,EmployeeMaster!C:C,0) -> Marketing | G4: Electronics | H4: 22 | I4: 22660 | J4: 26125 | K4: North | L4: =_xlfn.XLOOKUP(K4,RegionBenchmarks!A:A,RegionBenchmarks!B:B,"Not Found") -> 68500 | M4: =IF(I4>=J4,I4*5%,0) -> 0 | N4: =IF(I4>=J4,"Ture","No") -> No | O4: =TEXT(B4,"mmmm") -> May
A5: 531908 | B5: 44959 | C5: =_xlfn.XLOOKUP(D5,EmployeeMaster!A:A,EmployeeMaster!B:B,0) -> Lynda Smith | D5: EMP001 | E5: JAN | F5: =_xlfn.XLOOKUP(D5,EmployeeMaster!A:A,EmployeeMaster!C:C,0) -> Sales | G5: Stationery | H5: 55 | I5: 66165 | J5: 59434 | K5: North | L5: =_xlfn.XLOOKUP(K5,RegionBenchmarks!A:A,RegionBenchmarks!B:B,"Not Found") -> 68500 | M5: =IF(I5>=J5,I5*5%,0) -> 3308.25 | N5: =IF(I5>=J5,"Ture","No") -> Ture | O5: =TEXT(B5,"mmmm") -> February
A6: 208664 | B6: 45231 | C6: =_xlfn.XLOOKUP(D6,EmployeeMaster!A:A,EmployeeMaster!B:B,0) -> Martina Brands | D6: EMP007 | E6: JAN | F6: =_xlfn.XLOOKUP(D6,EmployeeMaster!A:A,EmployeeMaster!C:C,0) -> Marketing | G6: Electronics | H6: 34 | I6: 49606 | J6: 44952 | K6: North | L6: =_xlfn.XLOOKUP(K6,RegionBenchmarks!A:A,RegionBenchmarks!B:B,"Not Found") -> 68500 | M6: =IF(I6>=J6,I6*5%,0) -> 2480.3 | N6: =IF(I6>=J6,"Ture","No") -> Ture | O6: =TEXT(B6,"mmmm") -> November
A7: 690563 | B7: 45152 | C7: =_xlfn.XLOOKUP(D7,EmployeeMaster!A:A,EmployeeMaster!B:B,0) -> Ronn Robinson | D7: EMP003 | E7: JAN | F7: =_xlfn.XLOOKUP(D7,EmployeeMaster!A:A,EmployeeMaster!C:C,0) -> Sales | G7: Electronics | H7: 47 | I7: 63356 | J7: 63804 | K7: East | L7: =_xlfn.XLOOKUP(K7,RegionBenchmarks!A:A,RegionBenchmarks!B:B,"Not Found") -> 50000 | M7: =IF(I7>=J7,I7*5%,0) -> 0 | N7: =IF(I7>=J7,"Ture","No") -> No | O7: =TEXT(B7,"mmmm") -> August
A8: 484790 | B8: 45017 | C8: =_xlfn.XLOOKUP(D8,EmployeeMaster!A:A,EmployeeMaster!B:B,0) -> Fatima Zhang | D8: EMP006 | E8: JAN | F8: =_xlfn.XLOOKUP(D8,EmployeeMaster!A:A,EmployeeMaster!C:C,0) -> Sales | G8: Furniture | H8: 26 | I8: 28444 | J8: 27220 | K8: South | L8: =_xlfn.XLOOKUP(K8,RegionBenchmarks!A:A,RegionBenchmarks!B:B,"Not Found") -> 60000 | M8: =IF(I8>=J8,I8*5%,0) -> 1422.2 | N8: =IF(I8>=J8,"Ture","No") -> Ture | O8: =TEXT(B8,"mmmm") -> April
A9: 424434 | B9: 45128 | C9: =_xlfn.XLOOKUP(D9,EmployeeMaster!A:A,EmployeeMaster!B:B,0) -> Fatima Zhang | D9: EMP006 | E9: JAN | F9: =_xlfn.XLOOKUP(D9,EmployeeMaster!A:A,EmployeeMaster!C:C,0) -> Sales | G9: Stationery | H9: 58 | I9: 73660 | J9: 65437 | K9: South | L9: =_xlfn.XLOOKUP(K9,RegionBenchmarks!A:A,RegionBenchmarks!B:B,"Not Found") -> 60000 | M9: =IF(I9>=J9,I9*5%,0) -> 3683 | N9: =IF(I9>=J9,"Ture","No") -> Ture | O9: =TEXT(B9,"mmmm") -> July
A10: 190886 | B10: 45289 | C10: =_xlfn.XLOOKUP(D10,EmployeeMaster!A:A,EmployeeMaster!B:B,0) -> John Taylor | D10: EMP008 | E10: FEB | F10: =_xlfn.XLOOKUP(D10,EmployeeMaster!A:A,EmployeeMaster!C:C,0) -> Sales | G10: Stationery | H10: 54 | I10: 60858 | J10: 59657 | K10: East | L10: =_xlfn.XLOOKUP(K10,RegionBenchmarks!A:A,RegionBenchmarks!B:B,"Not Found") -> 50000 | M10: =IF(I10>=J10,I10*5%,0) -> 3042.9 | N10: =IF(I10>=J10,"Ture","No") -> Ture | O10: =TEXT(B10,"mmmm") -> December
A11: 655665 | B11: 45050 | C11: =_xlfn.XLOOKUP(D11,EmployeeMaster!A:A,EmployeeMaster!B:B,0) -> Joe Lyn | D11: EMP005 | E11: FEB | F11: =_xlfn.XLOOKUP(D11,EmployeeMaster!A:A,EmployeeMaster!C:C,0) -> Sales | G11: Stationery | H11: 60 | I11: 97980 | J11: 88473 | K11: Central | L11: =_xlfn.XLOOKUP(K11,RegionBenchmarks!A:A,RegionBenchmarks!B:B,"Not Found") -> 45000 | M11: =IF(I11>=J11,I11*5%,0) -> 4899 | N11: =IF(I11>=J11,"Ture","No") -> Ture | O11: =TEXT(B11,"mmmm") -> May
A12: 624861 | B12: 45132 | C12: =_xlfn.XLOOKUP(D12,EmployeeMaster!A:A,EmployeeMaster!B:B,0) -> Christi Davis | D12: EMP004 | E12: FEB | F12: =_xlfn.XLOOKUP(D12,EmployeeMaster!A:A,EmployeeMaster!C:C,0) -> Operations | G12: Furniture | H12: 24 | I12: 25104 | J12: 19270 | K12: West | L12: =_xlfn.XLOOKUP(K12,RegionBenchmarks!A:A,RegionBenchmarks!B:B,"Not Found") -> 55000 | M12: =IF(I12>=J12,I12*5%,0) -> 1255.2 | N12: =IF(I12>=J12,"Ture","No") -> Ture | O12: =TEXT(B12,"mmmm") -> July
A13: 279643 | B13: 44982 | C13: =_xlfn.XLOOKUP(D13,EmployeeMaster!A:A,EmployeeMaster!B:B,0) -> Raj Mehta | D13: EMP002 | E13: FEB | F13: =_xlfn.XLOOKUP(D13,EmployeeMaster!A:A,EmployeeMaster!C:C,0) -> Marketing | G13: Furniture | H13: 34 | I13: 64158 | J13: 67504 | K13: South | L13: =_xlfn.XLOOKUP(K13,RegionBenchmarks!A:A,RegionBenchmarks!B:B,"Not Found") -> 60000 | M13: =IF(I13>=J13,I13*5%,0) -> 0 | N13: =IF(I13>=J13,"Ture","No") -> No | O13: =TEXT(B13,"mmmm") -> February
... A101: 525728 | B101: 45265 | C101: =_xlfn.XLOOKUP(D101,EmployeeMaster!A:A,EmployeeMaster!B:B,0) -> Martina Brands | D101: EMP007 | E101: DEC | F101: =_xlfn.XLOOKUP(D101,EmployeeMaster!A:A,EmployeeMaster!C:C,0) -> Marketing | G101: Stationery | H101: 51 | I101: 71859 | J101: 72862 | K101: North | L101: =_xlfn.XLOOKUP(K101,RegionBenchmarks!A:A,RegionBenchmarks!B:B,"Not Found") -> 68500 | M101: =IF(I101>=J101,I101*5%,0) -> 0 | N101: =IF(I101>=J101,"Ture","No") -> No | O101: =TEXT(B101,"mmmm") -> December

Sheet RegionBenchmarks
A1: Region | B1: Benchmark Target
A2: North | B2: 68500
A3: South | B3: 60000
A4: East | B4: 50000
A5: West | B5: 55000
A6: Central | B6: 45000

Sheet Grouping
M2: Row Labels | N2: Sum of Revenue | R2: Row Labels | S2: Sum of Revenue
A3: Row Labels | B3: Count of Transaction ID | G3: Row Labels | H3: Sum of Units Sold | M3: EMP005 | N3: 1086352 | R3: West | S3: 710424
A4: Marketing | B4: 25 | G4: EMP001 | H4: 366 | M4: EMP002 | N4: 845449 | R4: Central | S4: 1086352
A5: Qtr1 | B5: 6 | G5: 20000-39999 | H5: 27 | M5: EMP006 | N5: 724087 | R5: North | S5: 1149809
A6: Qtr2 | B6: 4 | G6: 40000-59999 | H6: 284 | M6: EMP004 | N6: 710424 | R6: East | S6: 1345160
A7: Qtr3 | B7: 2 | G7: 60000-79999 | H7: 55 | M7: EMP003 | N7: 698662 | R7: South | S7: 1569536
A8: Qtr4 | B8: 13 | G8: EMP002 | H8: 548 | M8: EMP007 | N8: 652115 | R8: Grand Total | S8: 5861281
A9: Operations | B9: 15 | G9: 20000-39999 | H9: 44 | M9: EMP008 | N9: 646498
A10: Qtr2 | B10: 3 | G10: 40000-59999 | H10: 105 | M10: EMP001 | N10: 497694
A11: Qtr3 | B11: 6 | G11: 60000-79999 | H11: 236 | M11: Grand Total | N11: 5861281
A12: Qtr4 | B12: 6 | G12: 80000-99999 | H12: 163
A13: Sales | B13: 60 | G13: EMP003 | H13: 473
A14: Qtr1 | B14: 17 | G14: 40000-59999 | H14: 226
A15: Qtr2 | B15: 13 | G15: 60000-79999 | H15: 82
A16: Qtr3 | B16: 10 | G16: 80000-99999 | H16: 165
A17: Qtr4 | B17: 20 | G17: EMP004 | H17: 516
A18: Grand Total | B18: 100 | G18: 20000-39999 | H18: 135
G19: 40000-59999 | H19: 209
G20: 60000-79999 | H20: 172
G21: EMP005 | H21: 694
G22: 20000-39999 | H22: 22
G23: 40000-59999 | H23: 56
G24: 60000-79999 | H24: 281
G25: 80000-99999 | H25: 276
G26: 100000-119999 | H26: 59
G27: EMP006 | H27: 517
G28: 20000-39999 | H28: 81
G29: 40000-59999 | H29: 235
G30: 60000-79999 | H30: 201
... G42: Grand Total | H42: 4064
